<?xml version="1.0"?>

<robot name="rover" xmlns:xacro="http://www.ros.org/wiki/xacro" xmlns:gazebo="http://gazebosim.org/schema">>
  <!-- Declaring Constants -->
  <xacro:property name="wheel_radius" value="0.3" />
  <xacro:property name="wheel_length" value="0.1" />


  <!-- Base link -->
  <link name="base_link">
    <visual>
      <origin xyz="0 0 0" rpy="0 0 0"/>
      <geometry>
        <box size="2.5 1.5 0.1" />
      </geometry>
      <material name="green">
        <color rgba="0.2 1 0.2 1"/>
      </material>
    </visual>
    <inertial>
      <origin xyz="0 0 0.6" rpy="0 0 0" />
      <mass value="1" />
      <inertia ixx="1" ixy="0" ixz="0" iyy="1" iyz="0" izz="1" />
    </inertial>
  </link>

  <!-- Wheels go BRRRRR -->
  <xacro:macro name="wheel" params="name origin">
    <link name="${name}">
    <xacro:property name="tilt" value="${pi/2} 0 0" />

      <visual>
        <origin xyz="${origin}" rpy="${tilt}" />
        <material name="blue">
          <color rgba="0.2 0.2 1 1"/>
        </material>
        <geometry>
          <cylinder radius="${wheel_radius}" length="${wheel_length}" />
        </geometry>
      </visual>
      <collision>
        <origin xyz="${origin}" rpy="${tilt}"/>
        <geometry>
          <cylinder radius="${wheel_radius}" length="${wheel_length}" />
        </geometry>
      </collision>
      <inertial>
        <origin xyz="${origin}" rpy="${tilt}" />
        <mass value="0.5" />
        <inertia ixx="1" ixy="0" ixz="0" iyy="1" iyz="0" izz="1" />
      </inertial>
    </link>
    <joint name="${name}_joint" type="continuous">
      <parent link="base_link" />
      <child link="${name}" />
      <origin xyz="${origin}" rpy="0 0 0" />
      <axis xyz="0 1 0" />
    </joint>
  </xacro:macro>

  <!-- Instantiate wheels -->
  <xacro:wheel name="front_left_wheel" origin="-0.2 0.2 0" />
  <xacro:wheel name="front_right_wheel" origin="0.2 0.2 0" />
  <xacro:wheel name="rear_left_wheel" origin="-0.2 -0.2 0" />
  <xacro:wheel name="rear_right_wheel" origin="0.2 -0.2 0" />
  
  <!-- <gazebo>
    <plugin name="gazebo_ros_control" filename="libgazebo_ros2_control.so">
      <ros>
        <namespace>/rover</namespace>
      </ros>
      <robotSimType>gazebo_ros2_control/GazeboSystem</robotSimType>
      <robotParam>robot_description</robotParam>
    </plugin>
  </gazebo> -->

  <gazebo reference="base_link">
    <material>Gazebo/Green</material>
  </gazebo>

  <gazebo reference="slider_link">
    <material>Gazebo/Blue</material>
  </gazebo>

</robot>
